Workbook
Name BeginningInventory: 'Aggregate Planning'!$C$6
Name LaborStandard: 'Aggregate Planning'!$C$8

Sheet Assumptions
B2: Team: SONY
B4: Yong-Qi Gao
B5: Berta Leach
B6: Ivan Ushakov
B7: Huiyun Zhu
B10: Menu | F10: Summary
C12: Relevant tabs
B13: Data | C13: Sony Black (Cleaned)
C14: Sony Silver (Cleaned)
C15: Sony Black (Aggregated)
C16: Sony Silver (Aggregated)
C17: Sony Data (Aggregated)
B18: Forecasting | C18: Forecast Validation
C19: Parameters Optimisation
B20: Supply and inventory management | C20: Aggregate Planning
C21: Initial MPS and RCCP
C22: Authorised MPS
C23: MRP
C24: EOQ
C25: EPQ
C26: Discount model
C27: Inventory management Models
B32: Helper tabs | C32: (ACF Helper)
C33: (EOQ v EPQ helper)

Sheet Black (Cleaned)
A1: Assumptions
C2: Cleaned Sales data for SONY WH1000-MX5 Black | S2: Helpers
S3: First correction | V3: Second correction
F4: Date Time | G4: Date Time | H4: Item Qty | I4: lower boundary of IC | J4: upper boundary IC | K4: Cleaning (IC =95%) | L4: Sales data after first correction | M4: lower boundary IC | N4: upper boundary IC | O4: Cleaning (IC =95%) | P4: Sales data after 2nd correc. | Q4: Cleaned data | S4: mean | T4: sigma | V4: mean | W4: sigma
F5: 45561.423 | G5: 45561.423 | H5: 3328 | I5: =$S$5-$T$5*1.96 -> -1017182.2 | J5: =$S$5+$T$5*1.96 -> 1049634.1 | K5: =IF(AND(H5>=I5,H5<=J5),"Good","For Replacement") -> Good | L5: =IF(K5="Good",H5,(H6+H4)/2) -> 3328 | M5: =$V$5-$W$5*1.96 -> -13975.836 | N5: =$V$5+$W$5*1.96 -> 20870.015 | O5: =IF(AND(L5>=M5,L5<=N5),"Good","For Replacement") -> Good | P5: =IF(O5="Good",L5,(L6+L4)/2) -> 3328 | Q5: =P5 -> 3328 | S5: =AVERAGE(H5:H1706) -> 16225.977 | T5: =STDEV(H5:H1706) -> 527249.05 | V5: =AVERAGE(L5:L1706) -> 3447.0893 | W5: =STDEV(L5:L1706) -> 8889.2477
F6: 45560.885 | G6: 45560.885 | H6: 3521 | I6: =$S$5-$T$5*1.96 -> -1017182.2 | J6: =$S$5+$T$5*1.96 -> 1049634.1 | K6: =IF(AND(H6>=I6,H6<=J6),"Good","For Replacement") -> Good | L6: =IF(K6="Good",H6,(H7+H5)/2) -> 3521 | M6: =$V$5-$W$5*1.96 -> -13975.836 | N6: =$V$5+$W$5*1.96 -> 20870.015 | O6: =IF(AND(L6>=M6,L6<=N6),"Good","For Replacement") -> Good | P6: =IF(O6="Good",L6,(L7+L5)/2) -> 3521 | Q6: =P6 -> 3521
F7: 45560.326 | G7: 45560.326 | H7: 3680 | I7: =$S$5-$T$5*1.96 -> -1017182.2 | J7: =$S$5+$T$5*1.96 -> 1049634.1 | K7: =IF(AND(H7>=I7,H7<=J7),"Good","For Replacement") -> Good | L7: =IF(K7="Good",H7,(H8+H6)/2) -> 3680 | M7: =$V$5-$W$5*1.96 -> -13975.836 | N7: =$V$5+$W$5*1.96 -> 20870.015 | O7: =IF(AND(L7>=M7,L7<=N7),"Good","For Replacement") -> Good | P7: =IF(O7="Good",L7,(L8+L6)/2) -> 3680 | Q7: =P7 -> 3680
F8: 45559.729 | G8: 45559.729 | H8: 3546 | I8: =$S$5-$T$5*1.96 -> -1017182.2 | J8: =$S$5+$T$5*1.96 -> 1049634.1 | K8: =IF(AND(H8>=I8,H8<=J8),"Good","For Replacement") -> Good | L8: =IF(K8="Good",H8,(H9+H7)/2) -> 3546 | M8: =$V$5-$W$5*1.96 -> -13975.836 | N8: =$V$5+$W$5*1.96 -> 20870.015 | O8: =IF(AND(L8>=M8,L8<=N8),"Good","For Replacement") -> Good | P8: =IF(O8="Good",L8,(L9+L7)/2) -> 3546 | Q8: =P8 -> 3546
F9: 45559.116 | G9: 45559.116 | H9: 4032 | I9: =$S$5-$T$5*1.96 -> -1017182.2 | J9: =$S$5+$T$5*1.96 -> 1049634.1 | K9: =IF(AND(H9>=I9,H9<=J9),"Good","For Replacement") -> Good | L9: =IF(K9="Good",H9,(H10+H8)/2) -> 4032 | M9: =$V$5-$W$5*1.96 -> -13975.836 | N9: =$V$5+$W$5*1.96 -> 20870.015 | O9: =IF(AND(L9>=M9,L9<=N9),"Good","For Replacement") -> Good | P9: =IF(O9="Good",L9,(L10+L8)/2) -> 4032 | Q9: =P9 -> 4032
F10: 45558.51 | G10: 45558.51 | H10: 3511 | I10: =$S$5-$T$5*1.96 -> -1017182.2 | J10: =$S$5+$T$5*1.96 -> 1049634.1 | K10: =IF(AND(H10>=I10,H10<=J10),"Good","For Replacement") -> Good | L10: =IF(K10="Good",H10,(H11+H9)/2) -> 3511 | M10: =$V$5-$W$5*1.96 -> -13975.836 | N10: =$V$5+$W$5*1.96 -> 20870.015 | O10: =IF(AND(L10>=M10,L10<=N10),"Good","For Replacement") -> Good | P10: =IF(O10="Good",L10,(L11+L9)/2) -> 3511 | Q10: =P10 -> 3511
F11: 45555.591 | G11: 45555.591 | H11: 3740 | I11: =$S$5-$T$5*1.96 -> -1017182.2 | J11: =$S$5+$T$5*1.96 -> 1049634.1 | K11: =IF(AND(H11>=I11,H11<=J11),"Good","For Replacement") -> Good | L11: =IF(K11="Good",H11,(H12+H10)/2) -> 3740 | M11: =$V$5-$W$5*1.96 -> -13975.836 | N11: =$V$5+$W$5*1.96 -> 20870.015 | O11: =IF(AND(L11>=M11,L11<=N11),"Good","For Replacement") -> Good | P11: =IF(O11="Good",L11,(L12+L10)/2) -> 3740 | Q11: =P11 -> 3740
F12: 45555.058 | G12: 45555.058 | H12: 3367 | I12: =$S$5-$T$5*1.96 -> -1017182.2 | J12: =$S$5+$T$5*1.96 -> 1049634.1 | K12: =IF(AND(H12>=I12,H12<=J12),"Good","For Replacement") -> Good | L12: =IF(K12="Good",H12,(H13+H11)/2) -> 3367 | M12: =$V$5-$W$5*1.96 -> -13975.836 | N12: =$V$5+$W$5*1.96 -> 20870.015 | O12: =IF(AND(L12>=M12,L12<=N12),"Good","For Replacement") -> Good | P12: =IF(O12="Good",L12,(L13+L11)/2) -> 3367 | Q12: =P12 -> 3367
F13: 45554.475 | G13: 45554.475 | H13: 3264 | I13: =$S$5-$T$5*1.96 -> -1017182.2 | J13: =$S$5+$T$5*1.96 -> 1049634.1 | K13: =IF(AND(H13>=I13,H13<=J13),"Good","For Replacement") -> Good | L13: =IF(K13="Good",H13,(H14+H12)/2) -> 3264 | M13: =$V$5-$W$5*1.96 -> -13975.836 | N13: =$V$5+$W$5*1.96 -> 20870.015 | O13: =IF(AND(L13>=M13,L13<=N13),"Good","For Replacement") -> Good | P13: =IF(O13="Good",L13,(L14+L12)/2) -> 3264 | Q13: =P13 -> 3264
F14: 45553.867 | G14: 45553.867 | H14: 3735 | I14: =$S$5-$T$5*1.96 -> -1017182.2 | J14: =$S$5+$T$5*1.96 -> 1049634.1 | K14: =IF(AND(H14>=I14,H14<=J14),"Good","For Replacement") -> Good | L14: =IF(K14="Good",H14,(H15+H13)/2) -> 3735 | M14: =$V$5-$W$5*1.96 -> -13975.836 | N14: =$V$5+$W$5*1.96 -> 20870.015 | O14: =IF(AND(L14>=M14,L14<=N14),"Good","For Replacement") -> Good | P14: =IF(O14="Good",L14,(L15+L13)/2) -> 3735 | Q14: =P14 -> 3735
F15: 45553.26 | G15: 45553.26 | H15: 3338 | I15: =$S$5-$T$5*1.96 -> -1017182.2 | J15: =$S$5+$T$5*1.96 -> 1049634.1 | K15: =IF(AND(H15>=I15,H15<=J15),"Good","For Replacement") -> Good | L15: =IF(K15="Good",H15,(H16+H14)/2) -> 3338 | M15: =$V$5-$W$5*1.96 -> -13975.836 | N15: =$V$5+$W$5*1.96 -> 20870.015 | O15: =IF(AND(L15>=M15,L15<=N15),"Good","For Replacement") -> Good | P15: =IF(O15="Good",L15,(L16+L14)/2) -> 3338 | Q15: =P15 -> 3338
F16: 45552.721 | G16: 45552.721 | H16: 3890 | I16: =$S$5-$T$5*1.96 -> -1017182.2 | J16: =$S$5+$T$5*1.96 -> 1049634.1 | K16: =IF(AND(H16>=I16,H16<=J16),"Good","For Replacement") -> Good | L16: =IF(K16="Good",H16,(H17+H15)/2) -> 3890 | M16: =$V$5-$W$5*1.96 -> -13975.836 | N16: =$V$5+$W$5*1.96 -> 20870.015 | O16: =IF(AND(L16>=M16,L16<=N16),"Good","For Replacement") -> Good | P16: =IF(O16="Good",L16,(L17+L15)/2) -> 3890 | Q16: =P16 -> 3890
F17: 45552.181 | G17: 45552.181 | H17: 3352 | I17: =$S$5-$T$5*1.96 -> -1017182.2 | J17: =$S$5+$T$5*1.96 -> 1049634.1 | K17: =IF(AND(H17>=I17,H17<=J17),"Good","For Replacement") -> Good | L17: =IF(K17="Good",H17,(H18+H16)/2) -> 3352 | M17: =$V$5-$W$5*1.96 -> -13975.836 | N17: =$V$5+$W$5*1.96 -> 20870.015 | O17: =IF(AND(L17>=M17,L17<=N17),"Good","For Replacement") -> Good | P17: =IF(O17="Good",L17,(L18+L16)/2) -> 3352 | Q17: =P17 -> 3352
... F1706: 44197.261 | G1706: 44197.261 | H1706: 2128 | I1706: =$S$5-$T$5*1.96 -> -1017182.2 | J1706: =$S$5+$T$5*1.96 -> 1049634.1 | K1706: =IF(AND(H1706>=I1706,H1706<=J1706),"Good","For Replacement") -> Good | L1706: =IF(K1706="Good",H1706,(H1707+H1705)/2) -> 2128 | M1706: =$V$5-$W$5*1.96 -> -13975.836 | N1706: =$V$5+$W$5*1.96 -> 20870.015 | O1706: =IF(AND(L1706>=M1706,L1706<=N1706),"Good","For Replacement") -> Good | P1706: =IF(O1706="Good",L1706,(L1707+L1705)/2) -> 2128 | Q1706: =P1706 -> 2128

Sheet Silver (Cleaned)
A1: Assumptions
C2: Cleaned Sales Data for SONY WH1000-MX5 Silver | T2: Helpers
T3: First correction | W3: Second correction
F4: Date Time | G4: Date Time | H4: Item Qty | I4: lower boundary | J4: upper boundary | K4: Cleaning (IC =95%) | L4: Sales data after first correction | M4: lower boundary IC | N4: upper boundary IC | O4: Cleaning (IC =95%) | P4: Sales data after second correction | Q4: Cleaned data | T4: mean | U4: sigma | W4: mean | X4: sigma
F5: 45561.423 | G5: 45561.41 | H5: 1820 | I5: =$T$5-$U$5*1.96 -> -764.65463 | J5: =$T$5+$U$5*1.96 -> 4310.3027 | K5: =IF(AND(H5>=I5,H5<=J5),"Good","For Replacement") -> Good | L5: =IF(K5="Good",H5,(H6+H4)/2) -> 1820 | M5: =$W$5-$X$5*1.96 -> 674.62058 | N5: =$W$5+$X$5*1.96 -> 2778.6017 | O5: =IF(AND(L5>=M5,L5<=N5),"Good","For Replacement") -> Good | P5: =IF(O5="Good",L5,(L6+L4)/2) -> 1820 | Q5: =P5 -> 1820 | T5: =AVERAGE(H5:H1709) -> 1772.824 | U5: =STDEV(H5:H1709) -> 1294.632 | W5: =AVERAGE(L5:L1709) -> 1726.6111 | X5: =STDEV(L5:L1709) -> 536.72988
F6: 45560.885 | G6: 45560.809 | H6: 1820 | I6: =$T$5-$U$5*1.96 -> -764.65463 | J6: =$T$5+$U$5*1.96 -> 4310.3027 | K6: =IF(AND(H6>=I6,H6<=J6),"Good","For Replacement") -> Good | L6: =IF(K6="Good",H6,(H7+H5)/2) -> 1820 | M6: =$W$5-$X$5*1.96 -> 674.62058 | N6: =$W$5+$X$5*1.96 -> 2778.6017 | O6: =IF(AND(L6>=M6,L6<=N6),"Good","For Replacement") -> Good | P6: =IF(O6="Good",L6,(L7+L5)/2) -> 1820 | Q6: =P6 -> 1820
F7: 45560.326 | G7: 45560.21 | H7: 1804 | I7: =$T$5-$U$5*1.96 -> -764.65463 | J7: =$T$5+$U$5*1.96 -> 4310.3027 | K7: =IF(AND(H7>=I7,H7<=J7),"Good","For Replacement") -> Good | L7: =IF(K7="Good",H7,(H8+H6)/2) -> 1804 | M7: =$W$5-$X$5*1.96 -> 674.62058 | N7: =$W$5+$X$5*1.96 -> 2778.6017 | O7: =IF(AND(L7>=M7,L7<=N7),"Good","For Replacement") -> Good | P7: =IF(O7="Good",L7,(L8+L6)/2) -> 1804 | Q7: =P7 -> 1804
F8: 45559.729 | G8: 45559.607 | H8: 1946 | I8: =$T$5-$U$5*1.96 -> -764.65463 | J8: =$T$5+$U$5*1.96 -> 4310.3027 | K8: =IF(AND(H8>=I8,H8<=J8),"Good","For Replacement") -> Good | L8: =IF(K8="Good",H8,(H9+H7)/2) -> 1946 | M8: =$W$5-$X$5*1.96 -> 674.62058 | N8: =$W$5+$X$5*1.96 -> 2778.6017 | O8: =IF(AND(L8>=M8,L8<=N8),"Good","For Replacement") -> Good | P8: =IF(O8="Good",L8,(L9+L7)/2) -> 1946 | Q8: =P8 -> 1946
F9: 45559.116 | G9: 45559.02 | H9: 1842 | I9: =$T$5-$U$5*1.96 -> -764.65463 | J9: =$T$5+$U$5*1.96 -> 4310.3027 | K9: =IF(AND(H9>=I9,H9<=J9),"Good","For Replacement") -> Good | L9: =IF(K9="Good",H9,(H10+H8)/2) -> 1842 | M9: =$W$5-$X$5*1.96 -> 674.62058 | N9: =$W$5+$X$5*1.96 -> 2778.6017 | O9: =IF(AND(L9>=M9,L9<=N9),"Good","For Replacement") -> Good | P9: =IF(O9="Good",L9,(L10+L8)/2) -> 1842 | Q9: =P9 -> 1842
F10: 45558.51 | G10: 45558.458 | H10: 1678 | I10: =$T$5-$U$5*1.96 -> -764.65463 | J10: =$T$5+$U$5*1.96 -> 4310.3027 | K10: =IF(AND(H10>=I10,H10<=J10),"Good","For Replacement") -> Good | L10: =IF(K10="Good",H10,(H11+H9)/2) -> 1678 | M10: =$W$5-$X$5*1.96 -> 674.62058 | N10: =$W$5+$X$5*1.96 -> 2778.6017 | O10: =IF(AND(L10>=M10,L10<=N10),"Good","For Replacement") -> Good | P10: =IF(O10="Good",L10,(L11+L9)/2) -> 1678 | Q10: =P10 -> 1678
F11: 45555.591 | G11: 45555.709 | H11: 1919 | I11: =$T$5-$U$5*1.96 -> -764.65463 | J11: =$T$5+$U$5*1.96 -> 4310.3027 | K11: =IF(AND(H11>=I11,H11<=J11),"Good","For Replacement") -> Good | L11: =IF(K11="Good",H11,(H12+H10)/2) -> 1919 | M11: =$W$5-$X$5*1.96 -> 674.62058 | N11: =$W$5+$X$5*1.96 -> 2778.6017 | O11: =IF(AND(L11>=M11,L11<=N11),"Good","For Replacement") -> Good | P11: =IF(O11="Good",L11,(L12+L10)/2) -> 1919 | Q11: =P11 -> 1919
F12: 45555.058 | G12: 45555.166 | H12: 1912 | I12: =$T$5-$U$5*1.96 -> -764.65463 | J12: =$T$5+$U$5*1.96 -> 4310.3027 | K12: =IF(AND(H12>=I12,H12<=J12),"Good","For Replacement") -> Good | L12: =IF(K12="Good",H12,(H13+H11)/2) -> 1912 | M12: =$W$5-$X$5*1.96 -> 674.62058 | N12: =$W$5+$X$5*1.96 -> 2778.6017 | O12: =IF(AND(L12>=M12,L12<=N12),"Good","For Replacement") -> Good | P12: =IF(O12="Good",L12,(L13+L11)/2) -> 1912 | Q12: =P12 -> 1912
F13: 45554.475 | G13: 45554.63 | H13: 1868 | I13: =$T$5-$U$5*1.96 -> -764.65463 | J13: =$T$5+$U$5*1.96 -> 4310.3027 | K13: =IF(AND(H13>=I13,H13<=J13),"Good","For Replacement") -> Good | L13: =IF(K13="Good",H13,(H14+H12)/2) -> 1868 | M13: =$W$5-$X$5*1.96 -> 674.62058 | N13: =$W$5+$X$5*1.96 -> 2778.6017 | O13: =IF(AND(L13>=M13,L13<=N13),"Good","For Replacement") -> Good | P13: =IF(O13="Good",L13,(L14+L12)/2) -> 1868 | Q13: =P13 -> 1868
F14: 45553.867 | G14: 45554.101 | H14: 1685 | I14: =$T$5-$U$5*1.96 -> -764.65463 | J14: =$T$5+$U$5*1.96 -> 4310.3027 | K14: =IF(AND(H14>=I14,H14<=J14),"Good","For Replacement") -> Good | L14: =IF(K14="Good",H14,(H15+H13)/2) -> 1685 | M14: =$W$5-$X$5*1.96 -> 674.62058 | N14: =$W$5+$X$5*1.96 -> 2778.6017 | O14: =IF(AND(L14>=M14,L14<=N14),"Good","For Replacement") -> Good | P14: =IF(O14="Good",L14,(L15+L13)/2) -> 1685 | Q14: =P14 -> 1685
F15: 45553.26 | G15: 45553.553 | H15: 1766 | I15: =$T$5-$U$5*1.96 -> -764.65463 | J15: =$T$5+$U$5*1.96 -> 4310.3027 | K15: =IF(AND(H15>=I15,H15<=J15),"Good","For Replacement") -> Good | L15: =IF(K15="Good",H15,(H16+H14)/2) -> 1766 | M15: =$W$5-$X$5*1.96 -> 674.62058 | N15: =$W$5+$X$5*1.96 -> 2778.6017 | O15: =IF(AND(L15>=M15,L15<=N15),"Good","For Replacement") -> Good | P15: =IF(O15="Good",L15,(L16+L14)/2) -> 1766 | Q15: =P15 -> 1766
F16: 45552.721 | G16: 45552.964 | H16: 1713 | I16: =$T$5-$U$5*1.96 -> -764.65463 | J16: =$T$5+$U$5*1.96 -> 4310.3027 | K16: =IF(AND(H16>=I16,H16<=J16),"Good","For Replacement") -> Good | L16: =IF(K16="Good",H16,(H17+H15)/2) -> 1713 | M16: =$W$5-$X$5*1.96 -> 674.62058 | N16: =$W$5+$X$5*1.96 -> 2778.6017 | O16: =IF(AND(L16>=M16,L16<=N16),"Good","For Replacement") -> Good | P16: =IF(O16="Good",L16,(L17+L15)/2) -> 1713 | Q16: =P16 -> 1713
F17: 45552.181 | G17: 45552.368 | H17: 1861 | I17: =$T$5-$U$5*1.96 -> -764.65463 | J17: =$T$5+$U$5*1.96 -> 4310.3027 | K17: =IF(AND(H17>=I17,H17<=J17),"Good","For Replacement") -> Good | L17: =IF(K17="Good",H17,(H18+H16)/2) -> 1861 | M17: =$W$5-$X$5*1.96 -> 674.62058 | N17: =$W$5+$X$5*1.96 -> 2778.6017 | O17: =IF(AND(L17>=M17,L17<=N17),"Good","For Replacement") -> Good | P17: =IF(O17="Good",L17,(L18+L16)/2) -> 1861 | Q17: =P17 -> 1861
... F1706: 44197.261 | G1706: 44201.368 | H1706: 2016 | I1706: =$T$5-$U$5*1.96 -> -764.65463 | J1706: =$T$5+$U$5*1.96 -> 4310.3027 | K1706: =IF(AND(H1706>=I1706,H1706<=J1706),"Good","For Replacement") -> Good | L1706: =IF(K1706="Good",H1706,(H1707+H1705)/2) -> 2016 | M1706: =$W$5-$X$5*1.96 -> 674.62058 | N1706: =$W$5+$X$5*1.96 -> 2778.6017 | O1706: =IF(AND(L1706>=M1706,L1706<=N1706),"Good","For Replacement") -> Good | P1706: =IF(O1706="Good",L1706,(L1707+L1705)/2) -> 2016 | Q1706: =P1706 -> 2016
G1707: 44200.826 | H1707: 1761 | I1707: =$T$5-$U$5*1.96 -> -764.65463 | J1707: =$T$5+$U$5*1.96 -> 4310.3027 | K1707: =IF(AND(H1707>=I1707,H1707<=J1707),"Good","For Replacement") -> Good | L1707: =IF(K1707="Good",H1707,(H1708+H1706)/2) -> 1761 | M1707: =$W$5-$X$5*1.96 -> 674.62058 | N1707: =$W$5+$X$5*1.96 -> 2778.6017 | O1707: =IF(AND(L1707>=M1707,L1707<=N1707),"Good","For Replacement") -> Good | P1707: =IF(O1707="Good",L1707,(L1708+L1706)/2) -> 1761 | Q1707: =P1707 -> 1761
G1708: 44200.286 | H1708: 1966 | I1708: =$T$5-$U$5*1.96 -> -764.65463 | J1708: =$T$5+$U$5*1.96 -> 4310.3027 | K1708: =IF(AND(H1708>=I1708,H1708<=J1708),"Good","For Replacement") -> Good | L1708: =IF(K1708="Good",H1708,(H1709+H1707)/2) -> 1966 | M1708: =$W$5-$X$5*1.96 -> 674.62058 | N1708: =$W$5+$X$5*1.96 -> 2778.6017 | O1708: =IF(AND(L1708>=M1708,L1708<=N1708),"Good","For Replacement") -> Good | P1708: =IF(O1708="Good",L1708,(L1709+L1707)/2) -> 1966 | Q1708: =P1708 -> 1966
G1709: 44197.475 | H1709: 1521 | I1709: =$T$5-$U$5*1.96 -> -764.65463 | J1709: =$T$5+$U$5*1.96 -> 4310.3027 | K1709: =IF(AND(H1709>=I1709,H1709<=J1709),"Good","For Replacement") -> Good | L1709: =IF(K1709="Good",H1709,(H1710+H1708)/2) -> 1521 | M1709: =$W$5-$X$5*1.96 -> 674.62058 | N1709: =$W$5+$X$5*1.96 -> 2778.6017 | O1709: =IF(AND(L1709>=M1709,L1709<=N1709),"Good","For Replacement") -> Good | P1709: =IF(O1709="Good",L1709,(L1710+L1708)/2) -> 1521 | Q1709: =P1709 -> 1521

Sheet Black (Aggregated)
A1: Assumptions
C2: Aggregation of Sales Data for Only WH1000-MX5 Black
G4: Cleaned data SONY WH1000-MX5 Black | M4: Aggregated last 36M SONY WH1000-MX5 Black
G5: Date Time | H5: Clean Data | I5: Month | J5: helper column | L5: Month cnt (helper) | M5: Month | N5: Sum of Sales | P5: Summary
G6: ='Black (Cleaned)'!G5 -> 45561.423 | H6: ='Black (Cleaned)'!Q5 -> 3328 | I6: =TEXT(G6, "YYYY-MM") -> 2024-09 | J6: =TEXT(M6, "YYYY-MM") -> 2024-09 | L6: 1 | M6: 45536 | N6: =IF(L6<37,SUMIF(I:I, J6, H:H),"Out of Scope") -> 112872 | P6: Sum of Clean Data | Q6: Column Labels
G7: ='Black (Cleaned)'!G6 -> 45560.885 | H7: ='Black (Cleaned)'!Q6 -> 3521 | I7: =TEXT(G7, "YYYY-MM") -> 2024-09 | J7: =TEXT(M7, "YYYY-MM") -> 2024-08 | L7: =L6+1 -> 2 | M7: 45505 | N7: =IF(L7<37,SUMIF(I:I, J7, H:H),"Out of Scope") -> 90886 | P7: Row Labels | Q7: Jan | R7: Feb | S7: Mar | T7: Apr | U7: May | V7: Jun | W7: Jul | X7: Aug | Y7: Sep | Z7: Oct | AA7: Nov | AB7: Dec | AC7: Grand Total
G8: ='Black (Cleaned)'!G7 -> 45560.326 | H8: ='Black (Cleaned)'!Q7 -> 3680 | I8: =TEXT(G8, "YYYY-MM") -> 2024-09 | J8: =TEXT(M8, "YYYY-MM") -> 2024-07 | L8: =L7+1 -> 3 | M8: 45474 | N8: =IF(L8<37,SUMIF(I:I, J8, H:H),"Out of Scope") -> 88716 | P8: 2021 | Q8: 131274 | R8: 115805 | S8: 108273 | T8: 88454 | U8: 95250 | V8: 86653 | W8: 71870 | X8: 71480.5 | Y8: 104097 | Z8: 105878 | AA8: 146396 | AB8: 206971 | AC8: 1332401.5
G9: ='Black (Cleaned)'!G8 -> 45559.729 | H9: ='Black (Cleaned)'!Q8 -> 3546 | I9: =TEXT(G9, "YYYY-MM") -> 2024-09 | J9: =TEXT(M9, "YYYY-MM") -> 2024-06 | L9: =L8+1 -> 4 | M9: 45444 | N9: =IF(L9<37,SUMIF(I:I, J9, H:H),"Out of Scope") -> 100669 | P9: 2022 | Q9: 171166 | R9: 112402 | S9: 122690 | T9: 88678 | U9: 96735 | V9: 98843 | W9: 74539 | X9: 84181 | Y9: 112346 | Z9: 116187 | AA9: 163412 | AB9: 199766 | AC9: 1440945
G10: ='Black (Cleaned)'!G9 -> 45559.116 | H10: ='Black (Cleaned)'!Q9 -> 4032 | I10: =TEXT(G10, "YYYY-MM") -> 2024-09 | J10: =TEXT(M10, "YYYY-MM") -> 2024-05 | L10: =L9+1 -> 5 | M10: 45413 | N10: =IF(L10<37,SUMIF(I:I, J10, H:H),"Out of Scope") -> 116472 | P10: 2023 | Q10: 188781 | R10: 128220 | S10: 122870 | T10: 89010 | U10: 113131 | V10: 102145 | W10: 73332 | X10: 86770 | Y10: 111564 | Z10: 128256 | AA10: 163313 | AB10: 206038 | AC10: 1513430
G11: ='Black (Cleaned)'!G10 -> 45558.51 | H11: ='Black (Cleaned)'!Q10 -> 3511 | I11: =TEXT(G11, "YYYY-MM") -> 2024-09 | J11: =TEXT(M11, "YYYY-MM") -> 2024-04 | L11: =L10+1 -> 6 | M11: 45383 | N11: =IF(L11<37,SUMIF(I:I, J11, H:H),"Out of Scope") -> 105989 | P11: 2024 | Q11: 205208 | R11: 134180 | S11: 123627 | T11: 105989 | U11: 116472 | V11: 100669 | W11: 88716 | X11: 90886 | Y11: 112872 | AC11: 1078619
G12: ='Black (Cleaned)'!G11 -> 45555.591 | H12: ='Black (Cleaned)'!Q11 -> 3740 | I12: =TEXT(G12, "YYYY-MM") -> 2024-09 | J12: =TEXT(M12, "YYYY-MM") -> 2024-03 | L12: =L11+1 -> 7 | M12: 45352 | N12: =IF(L12<37,SUMIF(I:I, J12, H:H),"Out of Scope") -> 123627 | P12: Grand Total | Q12: 696429 | R12: 490607 | S12: 477460 | T12: 372131 | U12: 421588 | V12: 388310 | W12: 308457 | X12: 333317.5 | Y12: 440879 | Z12: 350321 | AA12: 473121 | AB12: 612775 | AC12: 5365395.5
G13: ='Black (Cleaned)'!G12 -> 45555.058 | H13: ='Black (Cleaned)'!Q12 -> 3367 | I13: =TEXT(G13, "YYYY-MM") -> 2024-09 | J13: =TEXT(M13, "YYYY-MM") -> 2024-02 | L13: =L12+1 -> 8 | M13: 45323 | N13: =IF(L13<37,SUMIF(I:I, J13, H:H),"Out of Scope") -> 134180
G14: ='Black (Cleaned)'!G13 -> 45554.475 | H14: ='Black (Cleaned)'!Q13 -> 3264 | I14: =TEXT(G14, "YYYY-MM") -> 2024-09 | J14: =TEXT(M14, "YYYY-MM") -> 2024-01 | L14: =L13+1 -> 9 | M14: 45292 | N14: =IF(L14<37,SUMIF(I:I, J14, H:H),"Out of Scope") -> 205208
G15: ='Black (Cleaned)'!G14 -> 45553.867 | H15: ='Black (Cleaned)'!Q14 -> 3735 | I15: =TEXT(G15, "YYYY-MM") -> 2024-09 | J15: =TEXT(M15, "YYYY-MM") -> 2023-12 | L15: =L14+1 -> 10 | M15: 45261 | N15: =IF(L15<37,SUMIF(I:I, J15, H:H),"Out of Scope") -> 206038
G16: ='Black (Cleaned)'!G15 -> 45553.26 | H16: ='Black (Cleaned)'!Q15 -> 3338 | I16: =TEXT(G16, "YYYY-MM") -> 2024-09 | J16: =TEXT(M16, "YYYY-MM") -> 2023-11 | L16: =L15+1 -> 11 | M16: 45231 | N16: =IF(L16<37,SUMIF(I:I, J16, H:H),"Out of Scope") -> 163313
G17: ='Black (Cleaned)'!G16 -> 45552.721 | H17: ='Black (Cleaned)'!Q16 -> 3890 | I17: =TEXT(G17, "YYYY-MM") -> 2024-09 | J17: =TEXT(M17, "YYYY-MM") -> 2023-10 | L17: =L16+1 -> 12 | M17: 45200 | N17: =IF(L17<37,SUMIF(I:I, J17, H:H),"Out of Scope") -> 128256
G18: ='Black (Cleaned)'!G17 -> 45552.181 | H18: ='Black (Cleaned)'!Q17 -> 3352 | I18: =TEXT(G18, "YYYY-MM") -> 2024-09 | J18: =TEXT(M18, "YYYY-MM") -> 2023-09 | L18: =L17+1 -> 13 | M18: 45170 | N18: =IF(L18<37,SUMIF(I:I, J18, H:H),"Out of Scope") -> 111564
G19: ='Black (Cleaned)'!G18 -> 45551.608 | H19: ='Black (Cleaned)'!Q18 -> 3327 | I19: =TEXT(G19, "YYYY-MM") -> 2024-09 | J19: =TEXT(M19, "YYYY-MM") -> 2023-08 | L19: =L18+1 -> 14 | M19: 45139 | N19: =IF(L19<37,SUMIF(I:I, J19, H:H),"Out of Scope") -> 86770
G20: ='Black (Cleaned)'!G19 -> 45551.059 | H20: ='Black (Cleaned)'!Q19 -> 3690 | I20: =TEXT(G20, "YYYY-MM") -> 2024-09 | J20: =TEXT(M20, "YYYY-MM") -> 2023-07 | L20: =L19+1 -> 15 | M20: 45108 | N20: =IF(L20<37,SUMIF(I:I, J20, H:H),"Out of Scope") -> 73332
G21: ='Black (Cleaned)'!G20 -> 45548.78 | H21: ='Black (Cleaned)'!Q20 -> 3655 | I21: =TEXT(G21, "YYYY-MM") -> 2024-09 | J21: =TEXT(M21, "YYYY-MM") -> 2023-06 | L21: =L20+1 -> 16 | M21: 45078 | N21: =IF(L21<37,SUMIF(I:I, J21, H:H),"Out of Scope") -> 102145
G22: ='Black (Cleaned)'!G21 -> 45548.181 | H22: ='Black (Cleaned)'!Q21 -> 3607 | I22: =TEXT(G22, "YYYY-MM") -> 2024-09 | J22: =TEXT(M22, "YYYY-MM") -> 2023-05 | L22: =L21+1 -> 17 | M22: 45047 | N22: =IF(L22<37,SUMIF(I:I, J22, H:H),"Out of Scope") -> 113131
G23: ='Black (Cleaned)'!G22 -> 45547.579 | H23: ='Black (Cleaned)'!Q22 -> 3246 | I23: =TEXT(G23, "YYYY-MM") -> 2024-09 | J23: =TEXT(M23, "YYYY-MM") -> 2023-04 | L23: =L22+1 -> 18 | M23: 45017 | N23: =IF(L23<37,SUMIF(I:I, J23, H:H),"Out of Scope") -> 89010
G24: ='Black (Cleaned)'!G23 -> 45547.015 | H24: ='Black (Cleaned)'!Q23 -> 3599 | I24: =TEXT(G24, "YYYY-MM") -> 2024-09 | J24: =TEXT(M24, "YYYY-MM") -> 2023-03 | L24: =L23+1 -> 19 | M24: 44986 | N24: =IF(L24<37,SUMIF(I:I, J24, H:H),"Out of Scope") -> 122870
... G50: ='Black (Cleaned)'!G49 -> 45525.865 | H50: ='Black (Cleaned)'!Q49 -> 2612 | I50: =TEXT(G50, "YYYY-MM") -> 2024-08 | J50: =TEXT(M50, "YYYY-MM") -> 2021-01 | L50: =L49+1 -> 45 | M50: 44197 | N50: =IF(L50<37,SUMIF(I:I, J50, H:H),"Out of Scope") -> Out of Scope
G51: ='Black (Cleaned)'!G50 -> 45525.309 | H51: ='Black (Cleaned)'!Q50 -> 2320 | I51: =TEXT(G51, "YYYY-MM") -> 2024-08 | J51: =TEXT(M51, "YYYY-MM") -> 1900-01
G52: ='Black (Cleaned)'!G51 -> 45524.735 | H52: ='Black (Cleaned)'!Q51 -> 2486 | I52: =TEXT(G52, "YYYY-MM") -> 2024-08 | J52: =TEXT(M52, "YYYY-MM") -> 1900-01
G53: ='Black (Cleaned)'!G52 -> 45524.146 | H53: ='Black (Cleaned)'!Q52 -> 2625 | I53: =TEXT(G53, "YYYY-MM") -> 2024-08 | J53: =TEXT(M53, "YYYY-MM") -> 1900-01
G54: ='Black (Cleaned)'!G53 -> 45523.581 | H54: ='Black (Cleaned)'!Q53 -> 2111 | I54: =TEXT(G54, "YYYY-MM") -> 2024-08 | J54: =TEXT(M54, "YYYY-MM") -> 1900-01
G55: ='Black (Cleaned)'!G54 -> 45520.696 | H55: ='Black (Cleaned)'!Q54 -> 2103 | I55: =TEXT(G55, "YYYY-MM") -> 2024-08 | J55: =TEXT(M55, "YYYY-MM") -> 1900-01
G56: ='Black (Cleaned)'!G55 -> 45520.13 | H56: ='Black (Cleaned)'!Q55 -> 2363 | I56: =TEXT(G56, "YYYY-MM") -> 2024-08 | J56: =TEXT(M56, "YYYY-MM") -> 1900-01
G57: ='Black (Cleaned)'!G56 -> 45519.587 | H57: ='Black (Cleaned)'!Q56 -> 2349 | I57: =TEXT(G57, "YYYY-MM") -> 2024-08 | J57: =TEXT(M57, "YYYY-MM") -> 1900-01
G58: ='Black (Cleaned)'!G57 -> 45519.017 | H58: ='Black (Cleaned)'!Q57 -> 2378 | I58: =TEXT(G58, "YYYY-MM") -> 2024-08 | J58: =TEXT(M58, "YYYY-MM") -> 1900-01
G59: ='Black (Cleaned)'!G58 -> 45518.41 | H59: ='Black (Cleaned)'!Q58 -> 2139 | I59: =TEXT(G59, "YYYY-MM") -> 2024-08 | J59: =TEXT(M59, "YYYY-MM") -> 1900-01
G60: ='Black (Cleaned)'!G59 -> 45517.869 | H60: ='Black (Cleaned)'!Q59 -> 2451 | I60: =TEXT(G60, "YYYY-MM") -> 2024-08 | J60: =TEXT(M60, "YYYY-MM") -> 1900-01
G61: ='Black (Cleaned)'!G60 -> 45517.265 | H61: ='Black (Cleaned)'!Q60 -> 2293 | I61: =TEXT(G61, "YYYY-MM") -> 2024-08 | J61: =TEXT(M61, "YYYY-MM") -> 1900-01
G62: ='Black (Cleaned)'!G61 -> 45516.705 | H62: ='Black (Cleaned)'!Q61 -> 2280 | I62: =TEXT(G62, "YYYY-MM") -> 2024-08 | J62: =TEXT(M62, "YYYY-MM") -> 1900-01
... G1707: ='Black (Cleaned)'!G1706 -> 44197.261 | H1707: ='Black (Cleaned)'!Q1706 -> 2128 | I1707: =TEXT(G1707, "YYYY-MM") -> 2021-01 | J1707: =TEXT(M1707, "YYYY-MM") -> 1900-01

Sheet Silver (Aggregated)
A1: Assumptions
C2: Aggregation of Sales data for ony WH1000-MX5 Silver
G4: Cleaned data SONY WH1000-MX5 Silver | M4: Aggregated last 36M SONY WH1000-MX5 Silver | P4: Summary
G5: Date Time | H5: Clean Data | I5: Month | J5: helper column | L5: Month cnt (helper) | M5: Month | N5: Sum of Sales | P5: Sum of Clean Data | Q5: Column Labels
G6: ='Silver (Cleaned)'!G5 -> 45561.41 | H6: ='Silver (Cleaned)'!Q5 -> 1820 | I6: =TEXT(G6, "YYYY-MM") -> 2024-09 | J6: =TEXT(M6, "YYYY-MM") -> 2024-09 | L6: ='Black (Aggregated)'!L6 -> 1 | M6: 45536 | N6: =IF(L6<37,SUMIF(I:I, J6, H:H),"Out of Scope") -> 57705 | P6: Row Labels | Q6: Jan | R6: Feb | S6: Mar | T6: Apr | U6: May | V6: Jun | W6: Jul | X6: Aug | Y6: Sep | Z6: Oct | AA6: Nov | AB6: Dec | AC6: Grand Total
G7: ='Silver (Cleaned)'!G6 -> 45560.809 | H7: ='Silver (Cleaned)'!Q6 -> 1820 | I7: =TEXT(G7, "YYYY-MM") -> 2024-09 | J7: =TEXT(M7, "YYYY-MM") -> 2024-08 | L7: ='Black (Aggregated)'!L7 -> 2 | M7: 45505 | N7: =IF(L7<37,SUMIF(I:I, J7, H:H),"Out of Scope") -> 58140 | P7: 2021 | Q7: 83333.5 | R7: 65073 | S7: 53224 | T7: 45934 | U7: 49472 | V7: 52318 | W7: 41171 | X7: 45435 | Y7: 60779 | Z7: 58854 | AA7: 83385.5 | AB7: 102522.5 | AC7: 741501.5
G8: ='Silver (Cleaned)'!G7 -> 45560.21 | H8: ='Silver (Cleaned)'!Q7 -> 1804 | I8: =TEXT(G8, "YYYY-MM") -> 2024-09 | J8: =TEXT(M8, "YYYY-MM") -> 2024-07 | L8: ='Black (Aggregated)'!L8 -> 3 | M8: 45474 | N8: =IF(L8<37,SUMIF(I:I, J8, H:H),"Out of Scope") -> 50461 | P8: 2022 | Q8: 93397.5 | R8: 63266 | S8: 58838 | T8: 49232 | U8: 57246 | V8: 53813 | W8: 42482 | X8: 51840 | Y8: 60565 | Z8: 58754 | AA8: 80660 | AB8: 102245.5 | AC8: 772339
G9: ='Silver (Cleaned)'!G8 -> 45559.607 | H9: ='Silver (Cleaned)'!Q8 -> 1946 | I9: =TEXT(G9, "YYYY-MM") -> 2024-09 | J9: =TEXT(M9, "YYYY-MM") -> 2024-06 | L9: ='Black (Aggregated)'!L9 -> 4 | M9: 45444 | N9: =IF(L9<37,SUMIF(I:I, J9, H:H),"Out of Scope") -> 53435 | P9: 2023 | Q9: 107744.5 | R9: 75007 | S9: 61321 | T9: 48871 | U9: 58469 | V9: 58342 | W9: 43882 | X9: 55306 | Y9: 63171 | Z9: 66299 | AA9: 85614 | AB9: 101606 | AC9: 825632.5
G10: ='Silver (Cleaned)'!G9 -> 45559.02 | H10: ='Silver (Cleaned)'!Q9 -> 1842 | I10: =TEXT(G10, "YYYY-MM") -> 2024-09 | J10: =TEXT(M10, "YYYY-MM") -> 2024-05 | L10: ='Black (Aggregated)'!L10 -> 5 | M10: 45413 | N10: =IF(L10<37,SUMIF(I:I, J10, H:H),"Out of Scope") -> 64106 | P10: 2024 | Q10: 114572.5 | R10: 76839.5 | S10: 58243 | T10: 56954 | U10: 64106 | V10: 53435 | W10: 50461 | X10: 58140 | Y10: 57705 | AC10: 590456
G11: ='Silver (Cleaned)'!G10 -> 45558.458 | H11: ='Silver (Cleaned)'!Q10 -> 1678 | I11: =TEXT(G11, "YYYY-MM") -> 2024-09 | J11: =TEXT(M11, "YYYY-MM") -> 2024-04 | L11: ='Black (Aggregated)'!L11 -> 6 | M11: 45383 | N11: =IF(L11<37,SUMIF(I:I, J11, H:H),"Out of Scope") -> 56954 | P11: Grand Total | Q11: 399048 | R11: 280185.5 | S11: 231626 | T11: 200991 | U11: 229293 | V11: 217908 | W11: 177996 | X11: 210721 | Y11: 242220 | Z11: 183907 | AA11: 249659.5 | AB11: 306374 | AC11: 2929929
G12: ='Silver (Cleaned)'!G11 -> 45555.709 | H12: ='Silver (Cleaned)'!Q11 -> 1919 | I12: =TEXT(G12, "YYYY-MM") -> 2024-09 | J12: =TEXT(M12, "YYYY-MM") -> 2024-03 | L12: ='Black (Aggregated)'!L12 -> 7 | M12: 45352 | N12: =IF(L12<37,SUMIF(I:I, J12, H:H),"Out of Scope") -> 58243
G13: ='Silver (Cleaned)'!G12 -> 45555.166 | H13: ='Silver (Cleaned)'!Q12 -> 1912 | I13: =TEXT(G13, "YYYY-MM") -> 2024-09 | J13: =TEXT(M13, "YYYY-MM") -> 2024-02 | L13: ='Black (Aggregated)'!L13 -> 8 | M13: 45323 | N13: =IF(L13<37,SUMIF(I:I, J13, H:H),"Out of Scope") -> 76839.5
G14: ='Silver (Cleaned)'!G13 -> 45554.63 | H14: ='Silver (Cleaned)'!Q13 -> 1868 | I14: =TEXT(G14, "YYYY-MM") -> 2024-09 | J14: =TEXT(M14, "YYYY-MM") -> 2024-01 | L14: ='Black (Aggregated)'!L14 -> 9 | M14: 45292 | N14: =IF(L14<37,SUMIF(I:I, J14, H:H),"Out of Scope") -> 114572.5
G15: ='Silver (Cleaned)'!G14 -> 45554.101 | H15: ='Silver (Cleaned)'!Q14 -> 1685 | I15: =TEXT(G15, "YYYY-MM") -> 2024-09 | J15: =TEXT(M15, "YYYY-MM") -> 2023-12 | L15: ='Black (Aggregated)'!L15 -> 10 | M15: 45261 | N15: =IF(L15<37,SUMIF(I:I, J15, H:H),"Out of Scope") -> 101606
G16: ='Silver (Cleaned)'!G15 -> 45553.553 | H16: ='Silver (Cleaned)'!Q15 -> 1766 | I16: =TEXT(G16, "YYYY-MM") -> 2024-09 | J16: =TEXT(M16, "YYYY-MM") -> 2023-11 | L16: ='Black (Aggregated)'!L16 -> 11 | M16: 45231 | N16: =IF(L16<37,SUMIF(I:I, J16, H:H),"Out of Scope") -> 85614
G17: ='Silver (Cleaned)'!G16 -> 45552.964 | H17: ='Silver (Cleaned)'!Q16 -> 1713 | I17: =TEXT(G17, "YYYY-MM") -> 2024-09 | J17: =TEXT(M17, "YYYY-MM") -> 2023-10 | L17: ='Black (Aggregated)'!L17 -> 12 | M17: 45200 | N17: =IF(L17<37,SUMIF(I:I, J17, H:H),"Out of Scope") -> 66299
G18: ='Silver (Cleaned)'!G17 -> 45552.368 | H18: ='Silver (Cleaned)'!Q17 -> 1861 | I18: =TEXT(G18, "YYYY-MM") -> 2024-09 | J18: =TEXT(M18, "YYYY-MM") -> 2023-09 | L18: ='Black (Aggregated)'!L18 -> 13 | M18: 45170 | N18: =IF(L18<37,SUMIF(I:I, J18, H:H),"Out of Scope") -> 63171
G19: ='Silver (Cleaned)'!G18 -> 45551.78 | H19: ='Silver (Cleaned)'!Q18 -> 2052 | I19: =TEXT(G19, "YYYY-MM") -> 2024-09 | J19: =TEXT(M19, "YYYY-MM") -> 2023-08 | L19: ='Black (Aggregated)'!L19 -> 14 | M19: 45139 | N19: =IF(L19<37,SUMIF(I:I, J19, H:H),"Out of Scope") -> 55306
G20: ='Silver (Cleaned)'!G19 -> 45551.215 | H20: ='Silver (Cleaned)'!Q19 -> 1849 | I20: =TEXT(G20, "YYYY-MM") -> 2024-09 | J20: =TEXT(M20, "YYYY-MM") -> 2023-07 | L20: ='Black (Aggregated)'!L20 -> 15 | M20: 45108 | N20: =IF(L20<37,SUMIF(I:I, J20, H:H),"Out of Scope") -> 43882
G21: ='Silver (Cleaned)'!G20 -> 45548.894 | H21: ='Silver (Cleaned)'!Q20 -> 1932 | I21: =TEXT(G21, "YYYY-MM") -> 2024-09 | J21: =TEXT(M21, "YYYY-MM") -> 2023-06 | L21: ='Black (Aggregated)'!L21 -> 16 | M21: 45078 | N21: =IF(L21<37,SUMIF(I:I, J21, H:H),"Out of Scope") -> 58342
G22: ='Silver (Cleaned)'!G21 -> 45548.336 | H22: ='Silver (Cleaned)'!Q21 -> 1867 | I22: =TEXT(G22, "YYYY-MM") -> 2024-09 | J22: =TEXT(M22, "YYYY-MM") -> 2023-05 | L22: ='Black (Aggregated)'!L22 -> 17 | M22: 45047 | N22: =IF(L22<37,SUMIF(I:I, J22, H:H),"Out of Scope") -> 58469
G23: ='Silver (Cleaned)'!G22 -> 45547.782 | H23: ='Silver (Cleaned)'!Q22 -> 1748 | I23: =TEXT(G23, "YYYY-MM") -> 2024-09 | J23: =TEXT(M23, "YYYY-MM") -> 2023-04 | L23: ='Black (Aggregated)'!L23 -> 18 | M23: 45017 | N23: =IF(L23<37,SUMIF(I:I, J23, H:H),"Out of Scope") -> 48871
... G50: ='Silver (Cleaned)'!G49 -> 45526.054 | H50: ='Silver (Cleaned)'!Q49 -> 1702 | I50: =TEXT(G50, "YYYY-MM") -> 2024-08 | J50: =TEXT(M50, "YYYY-MM") -> 2021-01 | L50: ='Black (Aggregated)'!L50 -> 45 | M50: 44197 | N50: =IF(L50<37,SUMIF(I:I, J50, H:H),"Out of Scope") -> Out of Scope
G51: ='Silver (Cleaned)'!G50 -> 45525.487 | H51: ='Silver (Cleaned)'!Q50 -> 1530 | I51: =TEXT(G51, "YYYY-MM") -> 2024-08 | J51: =TEXT(M51, "YYYY-MM") -> 1900-01
G52: ='Silver (Cleaned)'!G51 -> 45524.933 | H52: ='Silver (Cleaned)'!Q51 -> 1654 | I52: =TEXT(G52, "YYYY-MM") -> 2024-08 | J52: =TEXT(M52, "YYYY-MM") -> 1900-01
G53: ='Silver (Cleaned)'!G52 -> 45524.399 | H53: ='Silver (Cleaned)'!Q52 -> 1365 | I53: =TEXT(G53, "YYYY-MM") -> 2024-08 | J53: =TEXT(M53, "YYYY-MM") -> 1900-01
G54: ='Silver (Cleaned)'!G53 -> 45523.814 | H54: ='Silver (Cleaned)'!Q53 -> 1519 | I54: =TEXT(G54, "YYYY-MM") -> 2024-08 | J54: =TEXT(M54, "YYYY-MM") -> 1900-01
G55: ='Silver (Cleaned)'!G54 -> 45523.22 | H55: ='Silver (Cleaned)'!Q54 -> 1542 | I55: =TEXT(G55, "YYYY-MM") -> 2024-08 | J55: =TEXT(M55, "YYYY-MM") -> 1900-01
G56: ='Silver (Cleaned)'!G55 -> 45520.968 | H56: ='Silver (Cleaned)'!Q55 -> 1567 | I56: =TEXT(G56, "YYYY-MM") -> 2024-08 | J56: =TEXT(M56, "YYYY-MM") -> 1900-01
G57: ='Silver (Cleaned)'!G56 -> 45520.421 | H57: ='Silver (Cleaned)'!Q56 -> 1397 | I57: =TEXT(G57, "YYYY-MM") -> 2024-08 | J57: =TEXT(M57, "YYYY-MM") -> 1900-01
G58: ='Silver (Cleaned)'!G57 -> 45519.819 | H58: ='Silver (Cleaned)'!Q57 -> 1262 | I58: =TEXT(G58, "YYYY-MM") -> 2024-08 | J58: =TEXT(M58, "YYYY-MM") -> 1900-01
G59: ='Silver (Cleaned)'!G58 -> 45519.258 | H59: ='Silver (Cleaned)'!Q58 -> 1292 | I59: =TEXT(G59, "YYYY-MM") -> 2024-08 | J59: =TEXT(M59, "YYYY-MM") -> 1900-01
G60: ='Silver (Cleaned)'!G59 -> 45518.722 | H60: ='Silver (Cleaned)'!Q59 -> 1335 | I60: =TEXT(G60, "YYYY-MM") -> 2024-08 | J60: =TEXT(M60, "YYYY-MM") -> 1900-01
G61: ='Silver (Cleaned)'!G60 -> 45518.108 | H61: ='Silver (Cleaned)'!Q60 -> 1433 | I61: =TEXT(G61, "YYYY-MM") -> 2024-08 | J61: =TEXT(M61, "YYYY-MM") -> 1900-01
G62: ='Silver (Cleaned)'!G61 -> 45517.564 | H62: ='Silver (Cleaned)'!Q61 -> 1308 | I62: =TEXT(G62, "YYYY-MM") -> 2024-08 | J62: =TEXT(M62, "YYYY-MM") -> 1900-01
... G1710: ='Silver (Cleaned)'!G1709 -> 44197.475 | H1710: ='Silver (Cleaned)'!Q1709 -> 1521 | I1710: =TEXT(G1710, "YYYY-MM") -> 2021-01 | J1710: =TEXT(M1710, "YYYY-MM") -> 1900-01

Sheet Total Sales
A1: Assumptions
C2: Combined Sales Data for Product Family: SONY WH1000-MX5
G5: Month | H5: Monthly Sales Black | I5: Monthly Sales Silver | J5: Monthly Sales Combined
G6: 45536 | H6: ='Black (Aggregated)'!N6 -> 112872 | I6: ='Silver (Aggregated)'!N6 -> 57705 | J6: =IF(OR(H6="Out of Scope",I6="Out of Scope"),"Out of Scope", H6+I6) -> 170577
G7: 45505 | H7: ='Black (Aggregated)'!N7 -> 90886 | I7: ='Silver (Aggregated)'!N7 -> 58140 | J7: =IF(OR(H7="Out of Scope",I7="Out of Scope"),"Out of Scope", H7+I7) -> 149026
G8: 45474 | H8: ='Black (Aggregated)'!N8 -> 88716 | I8: ='Silver (Aggregated)'!N8 -> 50461 | J8: =IF(OR(H8="Out of Scope",I8="Out of Scope"),"Out of Scope", H8+I8) -> 139177
G9: 45444 | H9: ='Black (Aggregated)'!N9 -> 100669 | I9: ='Silver (Aggregated)'!N9 -> 53435 | J9: =IF(OR(H9="Out of Scope",I9="Out of Scope"),"Out of Scope", H9+I9) -> 154104
G10: 45413 | H10: ='Black (Aggregated)'!N10 -> 116472 | I10: ='Silver (Aggregated)'!N10 -> 64106 | J10: =IF(OR(H10="Out of Scope",I10="Out of Scope"),"Out of Scope", H10+I10) -> 180578
G11: 45383 | H11: ='Black (Aggregated)'!N11 -> 105989 | I11: ='Silver (Aggregated)'!N11 -> 56954 | J11: =IF(OR(H11="Out of Scope",I11="Out of Scope"),"Out of Scope", H11+I11) -> 162943
G12: 45352 | H12: ='Black (Aggregated)'!N12 -> 123627 | I12: ='Silver (Aggregated)'!N12 -> 58243 | J12: =IF(OR(H12="Out of Scope",I12="Out of Scope"),"Out of Scope", H12+I12) -> 181870
G13: 45323 | H13: ='Black (Aggregated)'!N13 -> 134180 | I13: ='Silver (Aggregated)'!N13 -> 76839.5 | J13: =IF(OR(H13="Out of Scope",I13="Out of Scope"),"Out of Scope", H13+I13) -> 211019.5
G14: 45292 | H14: ='Black (Aggregated)'!N14 -> 205208 | I14: ='Silver (Aggregated)'!N14 -> 114572.5 | J14: =IF(OR(H14="Out of Scope",I14="Out of Scope"),"Out of Scope", H14+I14) -> 319780.5
G15: 45261 | H15: ='Black (Aggregated)'!N15 -> 206038 | I15: ='Silver (Aggregated)'!N15 -> 101606 | J15: =IF(OR(H15="Out of Scope",I15="Out of Scope"),"Out of Scope", H15+I15) -> 307644
G16: 45231 | H16: ='Black (Aggregated)'!N16 -> 163313 | I16: ='Silver (Aggregated)'!N16 -> 85614 | J16: =IF(OR(H16="Out of Scope",I16="Out of Scope"),"Out of Scope", H16+I16) -> 248927
G17: 45200 | H17: ='Black (Aggregated)'!N17 -> 128256 | I17: ='Silver (Aggregated)'!N17 -> 66299 | J17: =IF(OR(H17="Out of Scope",I17="Out of Scope"),"Out of Scope", H17+I17) -> 194555
... G28: 44866 | H28: ='Black (Aggregated)'!N28 -> 163412 | I28: ='Silver (Aggregated)'!N28 -> 80660 | J28: =IF(OR(H28="Out of Scope",I28="Out of Scope"),"Out of Scope", H28+I28) -> 244072
G29: 44835 | H29: ='Black (Aggregated)'!N29 -> 116187 | I29: ='Silver (Aggregated)'!N29 -> 58754 | J29: =IF(OR(H29="Out of Scope",I29="Out of Scope"),"Out of Scope", H29+I29) -> 174941 | L29: Summary
G30: 44805 | H30: ='Black (Aggregated)'!N30 -> 112346 | I30: ='Silver (Aggregated)'!N30 -> 60565 | J30: =IF(OR(H30="Out of Scope",I30="Out of Scope"),"Out of Scope", H30+I30) -> 172911 | L30: Sum of Monthly Sales Combined | M30: Column Labels
G31: 44774 | H31: ='Black (Aggregated)'!N31 -> 84181 | I31: ='Silver (Aggregated)'!N31 -> 51840 | J31: =IF(OR(H31="Out of Scope",I31="Out of Scope"),"Out of Scope", H31+I31) -> 136021 | L31: Row Labels | M31: Jan | N31: Feb | O31: Mar | P31: Apr | Q31: May | R31: Jun | S31: Jul | T31: Aug | U31: Sep | V31: Oct | W31: Nov | X31: Dec | Y31: Grand Total
G32: 44743 | H32: ='Black (Aggregated)'!N32 -> 74539 | I32: ='Silver (Aggregated)'!N32 -> 42482 | J32: =IF(OR(H32="Out of Scope",I32="Out of Scope"),"Out of Scope", H32+I32) -> 117021 | L32: 2021 | V32: 164732 | W32: 229781.5 | X32: 309493.5 | Y32: 704007
G33: 44713 | H33: ='Black (Aggregated)'!N33 -> 98843 | I33: ='Silver (Aggregated)'!N33 -> 53813 | J33: =IF(OR(H33="Out of Scope",I33="Out of Scope"),"Out of Scope", H33+I33) -> 152656 | L33: 2022 | M33: 264563.5 | N33: 175668 | O33: 181528 | P33: 137910 | Q33: 153981 | R33: 152656 | S33: 117021 | T33: 136021 | U33: 172911 | V33: 174941 | W33: 244072 | X33: 302011.5 | Y33: 2213284
G34: 44682 | H34: ='Black (Aggregated)'!N34 -> 96735 | I34: ='Silver (Aggregated)'!N34 -> 57246 | J34: =IF(OR(H34="Out of Scope",I34="Out of Scope"),"Out of Scope", H34+I34) -> 153981 | L34: 2023 | M34: 296525.5 | N34: 203227 | O34: 184191 | P34: 137881 | Q34: 171600 | R34: 160487 | S34: 117214 | T34: 142076 | U34: 174735 | V34: 194555 | W34: 248927 | X34: 307644 | Y34: 2339062.5
G35: 44652 | H35: ='Black (Aggregated)'!N35 -> 88678 | I35: ='Silver (Aggregated)'!N35 -> 49232 | J35: =IF(OR(H35="Out of Scope",I35="Out of Scope"),"Out of Scope", H35+I35) -> 137910 | L35: 2024 | M35: 319780.5 | N35: 211019.5 | O35: 181870 | P35: 162943 | Q35: 180578 | R35: 154104 | S35: 139177 | T35: 149026 | U35: 170577 | Y35: 1669075
G36: 44621 | H36: ='Black (Aggregated)'!N36 -> 122690 | I36: ='Silver (Aggregated)'!N36 -> 58838 | J36: =IF(OR(H36="Out of Scope",I36="Out of Scope"),"Out of Scope", H36+I36) -> 181528
G37: 44593 | H37: ='Black (Aggregated)'!N37 -> 112402 | I37: ='Silver (Aggregated)'!N37 -> 63266 | J37: =IF(OR(H37="Out of Scope",I37="Out of Scope"),"Out of Scope", H37+I37) -> 175668
G38: 44562 | H38: ='Black (Aggregated)'!N38 -> 171166 | I38: ='Silver (Aggregated)'!N38 -> 93397.5 | J38: =IF(OR(H38="Out of Scope",I38="Out of Scope"),"Out of Scope", H38+I38) -> 264563.5
G39: 44531 | H39: ='Black (Aggregated)'!N39 -> 206971 | I39: ='Silver (Aggregated)'!N39 -> 102522.5 | J39: =IF(OR(H39="Out of Scope",I39="Out of Scope"),"Out of Scope", H39+I39) -> 309493.5 | L39: Growth rate
G40: 44501 | H40: ='Black (Aggregated)'!N40 -> 146396 | I40: ='Silver (Aggregated)'!N40 -> 83385.5 | J40: =IF(OR(H40="Out of Scope",I40="Out of Scope"),"Out of Scope", H40+I40) -> 229781.5 | L40: YoY | M40: Sales, Qty | N40: Growth YOY %
G41: 44470 | H41: ='Black (Aggregated)'!N41 -> 105878 | I41: ='Silver (Aggregated)'!N41 -> 58854 | J41: =IF(OR(H41="Out of Scope",I41="Out of Scope"),"Out of Scope", H41+I41) -> 164732 | L41: Oct21-Sep22 | M41: =SUM(V32,W32,X32,M33,N33,O33,P33,Q33,R33,S33,T33,U33) -> 2196266.5
G42: 44440 | H42: ='Black (Aggregated)'!N42 -> Out of Scope | I42: ='Silver (Aggregated)'!N42 -> Out of Scope | J42: =IF(OR(H42="Out of Scope",I42="Out of Scope"),"Out of Scope", H42+I42) -> Out of Scope | L42: Oct22-Sep23 | M42: =SUM(V33,W33,X33,M34,N34,O34,P34,Q34,R34,S34,T34,U34) -> 2308961 | N42: =M42/M41-1 -> 0.051311851
G43: 44409 | H43: ='Black (Aggregated)'!N43 -> Out of Scope | I43: ='Silver (Aggregated)'!N43 -> Out of Scope | J43: =IF(OR(H43="Out of Scope",I43="Out of Scope"),"Out of Scope", H43+I43) -> Out of Scope | L43: Oct23-Sep24 | M43: =SUM(V34,W34,X34,M35,N35,O35,P35,Q35,R35,S35,T35,U35) -> 2420201 | N43: =M43/M42-1 -> 0.048177514
G44: 44378 | H44: ='Black (Aggregated)'!N44 -> Out of Scope | I44: ='Silver (Aggregated)'!N44 -> Out of Scope | J44: =IF(OR(H44="Out of Scope",I44="Out of Scope"),"Out of Scope", H44+I44) -> Out of Scope
G45: 44348 | H45: ='Black (Aggregated)'!N45 -> Out of Scope | I45: ='Silver (Aggregated)'!N45 -> Out of Scope | J45: =IF(OR(H45="Out of Scope",I45="Out of Scope"),"Out of Scope", H45+I45) -> Out of Scope
G46: 44317 | H46: ='Black (Aggregated)'!N46 -> Out of Scope | I46: ='Silver (Aggregated)'!N46 -> Out of Scope | J46: =IF(OR(H46="Out of Scope",I46="Out of Scope"),"Out of Scope", H46+I46) -> Out of Scope
G47: 44287 | H47: ='Black (Aggregated)'!N47 -> Out of Scope | I47: ='Silver (Aggregated)'!N47 -> Out of Scope | J47: =IF(OR(H47="Out of Scope",I47="Out of Scope"),"Out of Scope", H47+I47) -> Out of Scope
G48: 44256 | H48: ='Black (Aggregated)'!N48 -> Out of Scope | I48: ='Silver (Aggregated)'!N48 -> Out of Scope | J48: =IF(OR(H48="Out of Scope",I48="Out of Scope"),"Out of Scope", H48+I48) -> Out of Scope
G49: 44228 | H49: ='Black (Aggregated)'!N49 -> Out of Scope | I49: ='Silver (Aggregated)'!N49 -> Out of Scope | J49: =IF(OR(H49="Out of Scope",I49="Out of Scope"),"Out of Scope", H49+I49) -> Out of Scope
G50: 44197 | H50: ='Black (Aggregated)'!N50 -> Out of Scope | I50: ='Silver (Aggregated)'!N50 -> Out of Scope | J50: =IF(OR(H50="Out of Scope",I50="Out of Scope"),"Out of Scope", H50+I50) -> Out of Scope

Sheet (ACF Helper)
A1: Assumptions
C2: Correlation Coefficient Calculator
E4: Monthly Sales WH1000-MX5 Black
E5: Month | F5: Monthly Sales | H5: Cross Correlation | I5: =CORREL(OFFSET($F$6,0,0,37-I$7),OFFSET($F$6,I$7,0,37-I$7)) -> 0.67847758 | J5: =CORREL(OFFSET($F$6,0,0,37-J$7),OFFSET($F$6,J$7,0,37-J$7)) -> 0.24608088 | K5: =CORREL(OFFSET($F$6,0,0,37-K$7),OFFSET($F$6,K$7,0,37-K$7)) -> -0.081041555 | L5: =CORREL(OFFSET($F$6,0,0,37-L$7),OFFSET($F$6,L$7,0,37-L$7)) -> -0.36132762 | M5: =CORREL(OFFSET($F$6,0,0,37-M$7),OFFSET($F$6,M$7,0,37-M$7)) -> -0.54344471 | N5: =CORREL(OFFSET($F$6,0,0,37-N$7),OFFSET($F$6,N$7,0,37-N$7)) -> -0.59684056 | O5: =CORREL(OFFSET($F$6,0,0,37-O$7),OFFSET($F$6,O$7,0,37-O$7)) -> -0.62483099 | P5: =CORREL(OFFSET($F$6,0,0,37-P$7),OFFSET($F$6,P$7,0,37-P$7)) -> -0.46789222 | ... AQ5: =CORREL(OFFSET($F$6,0,0,37-AQ$7),OFFSET($F$6,AQ$7,0,37-AQ$7)) -> -1
E6: 45536 | F6: {=INDEX('Black (Aggregated)'!$N$6:$N$41,MATCH(E6,'Black (Aggregated)'!$M$6:$M$41,0))} -> 112872 | H6: ACF value | I6: =SUM(OFFSET(I9,I7,0,36-I7,1))/DEVSQ($F$6:$F$41) -> 0.67753855 | J6: =SUM(OFFSET(J9,J7,0,36-J7,1))/DEVSQ($F$6:$F$41) -> 0.24252878 | K6: =SUM(OFFSET(K9,K7,0,36-K7,1))/DEVSQ($F$6:$F$41) -> -0.078373257 | L6: =SUM(OFFSET(L9,L7,0,36-L7,1))/DEVSQ($F$6:$F$41) -> -0.32740671 | M6: =SUM(OFFSET(M9,M7,0,36-M7,1))/DEVSQ($F$6:$F$41) -> -0.47936838 | N6: =SUM(OFFSET(N9,N7,0,36-N7,1))/DEVSQ($F$6:$F$41) -> -0.5232282 | O6: =SUM(OFFSET(O9,O7,0,36-O7,1))/DEVSQ($F$6:$F$41) -> -0.54735443 | P6: =SUM(OFFSET(P9,P7,0,36-P7,1))/DEVSQ($F$6:$F$41) -> -0.4038093 | ... AQ6: =SUM(OFFSET(AQ9,AQ7,0,36-AQ7,1))/DEVSQ($F$6:$F$41) -> 0.0042715224
E7: 45505 | F7: {=INDEX('Black (Aggregated)'!$N$6:$N$41,MATCH(E7,'Black (Aggregated)'!$M$6:$M$41,0))} -> 90886 | H7: Lag | I7: 1 | J7: 2 | K7: 3 | L7: 4 | M7: 5 | N7: 6 | O7: 7 | P7: 8 | Q7: 9 | R7: 10 | S7: 11 | T7: 12 | U7: 13 | V7: 14 | W7: 15 | X7: 16 | Y7: 17 | Z7: 18 | AA7: 19 | AB7: 20 | AC7: 21 | AD7: 22 | AE7: 23 | AF7: 24 | AG7: 25 | AH7: 26 | AI7: 27 | AJ7: 28 | AK7: 29 | AL7: 30 | AM7: 31 | AN7: 32 | AO7: 33 | AP7: 34 | AQ7: 35
E8: 45474 | F8: {=INDEX('Black (Aggregated)'!$N$6:$N$41,MATCH(E8,'Black (Aggregated)'!$M$6:$M$41,0))} -> 88716 | H8: Counter
E9: 45444 | F9: {=INDEX('Black (Aggregated)'!$N$6:$N$41,MATCH(E9,'Black (Aggregated)'!$M$6:$M$41,0))} -> 100669 | H9: 1 | I9: =IF($H9>I$7,($F6-$F$42)*(OFFSET($F6,-I$7,0)-$F$42),"") | J9: =IF($H9>J$7,($F6-$F$42)*(OFFSET($F6,-J$7,0)-$F$42),"") | K9: =IF($H9>K$7,($F6-$F$42)*(OFFSET($F6,-K$7,0)-$F$42),"") | L9: =IF($H9>L$7,($F6-$F$42)*(OFFSET($F6,-L$7,0)-$F$42),"") | M9: =IF($H9>M$7,($F6-$F$42)*(OFFSET($F6,-M$7,0)-$F$42),"") | N9: =IF($H9>N$7,($F6-$F$42)*(OFFSET($F6,-N$7,0)-$F$42),"") | O9: =IF($H9>O$7,($F6-$F$42)*(OFFSET($F6,-O$7,0)-$F$42),"") | P9: =IF($H9>P$7,($F6-$F$42)*(OFFSET($F6,-P$7,0)-$F$42),"") | ... AQ9: =IF($H9>AQ$7,($F6-$F$42)*(OFFSET($F6,-AQ$7,0)-$F$42),"")
E10: 45413 | F10: {=INDEX('Black (Aggregated)'!$N$6:$N$41,MATCH(E10,'Black (Aggregated)'!$M$6:$M$41,0))} -> 116472 | H10: 2 | I10: =IF($H10>I$7,($F7-$F$42)*(OFFSET($F7,-I$7,0)-$F$42),"") -> 4.0381206e+08 | J10: =IF($H10>J$7,($F7-$F$42)*(OFFSET($F7,-J$7,0)-$F$42),"") | K10: =IF($H10>K$7,($F7-$F$42)*(OFFSET($F7,-K$7,0)-$F$42),"") | L10: =IF($H10>L$7,($F7-$F$42)*(OFFSET($F7,-L$7,0)-$F$42),"") | M10: =IF($H10>M$7,($F7-$F$42)*(OFFSET($F7,-M$7,0)-$F$42),"") | N10: =IF($H10>N$7,($F7-$F$42)*(OFFSET($F7,-N$7,0)-$F$42),"") | O10: =IF($H10>O$7,($F7-$F$42)*(OFFSET($F7,-O$7,0)-$F$42),"") | P10: =IF($H10>P$7,($F7-$F$42)*(OFFSET($F7,-P$7,0)-$F$42),"") | ... AQ10: =IF($H10>AQ$7,($F7-$F$42)*(OFFSET($F7,-AQ$7,0)-$F$42),"")
E11: 45383 | F11: {=INDEX('Black (Aggregated)'!$N$6:$N$41,MATCH(E11,'Black (Aggregated)'!$M$6:$M$41,0))} -> 105989 | H11: 3 | I11: =IF($H11>I$7,($F8-$F$42)*(OFFSET($F8,-I$7,0)-$F$42),"") -> 1.2226622e+09 | J11: =IF($H11>J$7,($F8-$F$42)*(OFFSET($F8,-J$7,0)-$F$42),"") -> 4.2966201e+08 | K11: =IF($H11>K$7,($F8-$F$42)*(OFFSET($F8,-K$7,0)-$F$42),"") | L11: =IF($H11>L$7,($F8-$F$42)*(OFFSET($F8,-L$7,0)-$F$42),"") | M11: =IF($H11>M$7,($F8-$F$42)*(OFFSET($F8,-M$7,0)-$F$42),"") | N11: =IF($H11>N$7,($F8-$F$42)*(OFFSET($F8,-N$7,0)-$F$42),"") | O11: =IF($H11>O$7,($F8-$F$42)*(OFFSET($F8,-O$7,0)-$F$42),"") | P11: =IF($H11>P$7,($F8-$F$42)*(OFFSET($F8,-P$7,0)-$F$42),"") | ... AQ11: =IF($H11>AQ$7,($F8-$F$42)*(OFFSET($F8,-AQ$7,0)-$F$42),"")
E12: 45352 | F12: {=INDEX('Black (Aggregated)'!$N$6:$N$41,MATCH(E12,'Black (Aggregated)'!$M$6:$M$41,0))} -> 123627 | H12: 4 | I12: =IF($H12>I$7,($F9-$F$42)*(OFFSET($F9,-I$7,0)-$F$42),"") -> 8.698049e+08 | J12: =IF($H12>J$7,($F9-$F$42)*(OFFSET($F9,-J$7,0)-$F$42),"") -> 8.1747444e+08 | K12: =IF($H12>K$7,($F9-$F$42)*(OFFSET($F9,-K$7,0)-$F$42),"") -> 2.8727289e+08 | L12: =IF($H12>L$7,($F9-$F$42)*(OFFSET($F9,-L$7,0)-$F$42),"") | M12: =IF($H12>M$7,($F9-$F$42)*(OFFSET($F9,-M$7,0)-$F$42),"") | N12: =IF($H12>N$7,($F9-$F$42)*(OFFSET($F9,-N$7,0)-$F$42),"") | O12: =IF($H12>O$7,($F9-$F$42)*(OFFSET($F9,-O$7,0)-$F$42),"") | P12: =IF($H12>P$7,($F9-$F$42)*(OFFSET($F9,-P$7,0)-$F$42),"") | ... AQ12: =IF($H12>AQ$7,($F9-$F$42)*(OFFSET($F9,-AQ$7,0)-$F$42),"")
E13: 45323 | F13: {=INDEX('Black (Aggregated)'!$N$6:$N$41,MATCH(E13,'Black (Aggregated)'!$M$6:$M$41,0))} -> 134180 | H13: 5 | I13: =IF($H13>I$7,($F10-$F$42)*(OFFSET($F10,-I$7,0)-$F$42),"") -> 2.0045739e+08 | J13: =IF($H13>J$7,($F10-$F$42)*(OFFSET($F10,-J$7,0)-$F$42),"") -> 2.9981571e+08 | K13: =IF($H13>K$7,($F10-$F$42)*(OFFSET($F10,-K$7,0)-$F$42),"") -> 2.8177776e+08 | L13: =IF($H13>L$7,($F10-$F$42)*(OFFSET($F10,-L$7,0)-$F$42),"") -> 99020971 | M13: =IF($H13>M$7,($F10-$F$42)*(OFFSET($F10,-M$7,0)-$F$42),"") | N13: =IF($H13>N$7,($F10-$F$42)*(OFFSET($F10,-N$7,0)-$F$42),"") | O13: =IF($H13>O$7,($F10-$F$42)*(OFFSET($F10,-O$7,0)-$F$42),"") | P13: =IF($H13>P$7,($F10-$F$42)*(OFFSET($F10,-P$7,0)-$F$42),"") | ... AQ13: =IF($H13>AQ$7,($F10-$F$42)*(OFFSET($F10,-AQ$7,0)-$F$42),"")
E14: 45292 | F14: {=INDEX('Black (Aggregated)'!$N$6:$N$41,MATCH(E14,'Black (Aggregated)'!$M$6:$M$41,0))} -> 205208 | H14: 6 | I14: =IF($H14>I$7,($F11-$F$42)*(OFFSET($F11,-I$7,0)-$F$42),"") -> 1.5623533e+08 | J14: =IF($H14>J$7,($F11-$F$42)*(OFFSET($F11,-J$7,0)-$F$42),"") -> 4.532593e+08 | K14: =IF($H14>K$7,($F11-$F$42)*(OFFSET($F11,-K$7,0)-$F$42),"") -> 6.7792092e+08 | L14: =IF($H14>L$7,($F11-$F$42)*(OFFSET($F11,-L$7,0)-$F$42),"") -> 6.3713487e+08 | M14: =IF($H14>M$7,($F11-$F$42)*(OFFSET($F11,-M$7,0)-$F$42),"") -> 2.2389883e+08 | N14: =IF($H14>N$7,($F11-$F$42)*(OFFSET($F11,-N$7,0)-$F$42),"") | O14: =IF($H14>O$7,($F11-$F$42)*(OFFSET($F11,-O$7,0)-$F$42),"") | P14: =IF($H14>P$7,($F11-$F$42)*(OFFSET($F11,-P$7,0)-$F$42),"") | ... AQ14: =IF($H14>AQ$7,($F11-$F$42)*(OFFSET($F11,-AQ$7,0)-$F$42),"")
E15: 45261 | F15: {=INDEX('Black (Aggregated)'!$N$6:$N$41,MATCH(E15,'Black (Aggregated)'!$M$6:$M$41,0))} -> 206038 | H15: 7 | I15: =IF($H15>I$7,($F12-$F$42)*(OFFSET($F12,-I$7,0)-$F$42),"") -> 21754129 | J15: =IF($H15>J$7,($F12-$F$42)*(OFFSET($F12,-J$7,0)-$F$42),"") -> 9620929.6 | K15: =IF($H15>K$7,($F12-$F$42)*(OFFSET($F12,-K$7,0)-$F$42),"") -> 27911585 | L15: =IF($H15>L$7,($F12-$F$42)*(OFFSET($F12,-L$7,0)-$F$42),"") -> 41746187 | M15: =IF($H15>M$7,($F12-$F$42)*(OFFSET($F12,-M$7,0)-$F$42),"") -> 39234592 | N15: =IF($H15>N$7,($F12-$F$42)*(OFFSET($F12,-N$7,0)-$F$42),"") -> 13787630 | O15: =IF($H15>O$7,($F12-$F$42)*(OFFSET($F12,-O$7,0)-$F$42),"") | P15: =IF($H15>P$7,($F12-$F$42)*(OFFSET($F12,-P$7,0)-$F$42),"") | ... AQ15: =IF($H15>AQ$7,($F12-$F$42)*(OFFSET($F12,-AQ$7,0)-$F$42),"")
E16: 45231 | F16: {=INDEX('Black (Aggregated)'!$N$6:$N$41,MATCH(E16,'Black (Aggregated)'!$M$6:$M$41,0))} -> 163313 | H16: 8 | I16: =IF($H16>I$7,($F13-$F$42)*(OFFSET($F13,-I$7,0)-$F$42),"") -> -10874605 | J16: =IF($H16>J$7,($F13-$F$42)*(OFFSET($F13,-J$7,0)-$F$42),"") -> -1.765939e+08 | K16: =IF($H16>K$7,($F13-$F$42)*(OFFSET($F13,-K$7,0)-$F$42),"") -> -78100003 | L16: =IF($H16>L$7,($F13-$F$42)*(OFFSET($F13,-L$7,0)-$F$42),"") -> -2.2657841e+08 | M16: =IF($H16>M$7,($F13-$F$42)*(OFFSET($F13,-M$7,0)-$F$42),"") -> -3.3888381e+08 | N16: =IF($H16>N$7,($F13-$F$42)*(OFFSET($F13,-N$7,0)-$F$42),"") -> -3.184954e+08 | O16: =IF($H16>O$7,($F13-$F$42)*(OFFSET($F13,-O$7,0)-$F$42),"") -> -1.119241e+08 | P16: =IF($H16>P$7,($F13-$F$42)*(OFFSET($F13,-P$7,0)-$F$42),"") | ... AQ16: =IF($H16>AQ$7,($F13-$F$42)*(OFFSET($F13,-AQ$7,0)-$F$42),"")
E17: 45200 | F17: {=INDEX('Black (Aggregated)'!$N$6:$N$41,MATCH(E17,'Black (Aggregated)'!$M$6:$M$41,0))} -> 128256 | H17: 9 | I17: =IF($H17>I$7,($F14-$F$42)*(OFFSET($F14,-I$7,0)-$F$42),"") -> 7.5562648e+08 | J17: =IF($H17>J$7,($F14-$F$42)*(OFFSET($F14,-J$7,0)-$F$42),"") -> -93083596 | K17: =IF($H17>K$7,($F14-$F$42)*(OFFSET($F14,-K$7,0)-$F$42),"") -> -1.5115948e+09 | L17: =IF($H17>L$7,($F14-$F$42)*(OFFSET($F14,-L$7,0)-$F$42),"") -> -6.6851433e+08 | M17: =IF($H17>M$7,($F14-$F$42)*(OFFSET($F14,-M$7,0)-$F$42),"") -> -1.9394482e+09 | N17: =IF($H17>N$7,($F14-$F$42)*(OFFSET($F14,-N$7,0)-$F$42),"") -> -2.9007513e+09 | O17: =IF($H17>O$7,($F14-$F$42)*(OFFSET($F14,-O$7,0)-$F$42),"") -> -2.7262321e+09 | P17: =IF($H17>P$7,($F14-$F$42)*(OFFSET($F14,-P$7,0)-$F$42),"") -> -9.5803923e+08 | ... AQ17: =IF($H17>AQ$7,($F14-$F$42)*(OFFSET($F14,-AQ$7,0)-$F$42),"")
E18: 45170 | F18: {=INDEX('Black (Aggregated)'!$N$6:$N$41,MATCH(E18,'Black (Aggregated)'!$M$6:$M$41,0))} -> 111564 | H18: 10 | I18: =IF($H18>I$7,($F15-$F$42)*(OFFSET($F15,-I$7,0)-$F$42),"") -> 6.5347043e+09 | J18: =IF($H18>J$7,($F15-$F$42)*(OFFSET($F15,-J$7,0)-$F$42),"") -> 7.6342481e+08 | K18: =IF($H18>K$7,($F15-$F$42)*(OFFSET($F15,-K$7,0)-$F$42),"") -> -94044252 | L18: =IF($H18>L$7,($F15-$F$42)*(OFFSET($F15,-L$7,0)-$F$42),"") -> -1.527195e+09 | M18: =IF($H18>M$7,($F15-$F$42)*(OFFSET($F15,-M$7,0)-$F$42),"") -> -6.7541364e+08 | N18: =IF($H18>N$7,($F15-$F$42)*(OFFSET($F15,-N$7,0)-$F$42),"") -> -1.959464e+09 | O18: =IF($H18>O$7,($F15-$F$42)*(OFFSET($F15,-O$7,0)-$F$42),"") -> -2.9306881e+09 | P18: =IF($H18>P$7,($F15-$F$42)*(OFFSET($F15,-P$7,0)-$F$42),"") -> -2.7543678e+09 | ... AQ18: =IF($H18>AQ$7,($F15-$F$42)*(OFFSET($F15,-AQ$7,0)-$F$42),"")
E19: 45139 | F19: {=INDEX('Black (Aggregated)'!$N$6:$N$41,MATCH(E19,'Black (Aggregated)'!$M$6:$M$41,0))} -> 86770 | H19: 11 | I19: =IF($H19>I$7,($F16-$F$42)*(OFFSET($F16,-I$7,0)-$F$42),"") -> 3.1305855e+09 | J19: =IF($H19>J$7,($F16-$F$42)*(OFFSET($F16,-J$7,0)-$F$42),"") -> 3.0986067e+09 | K19: =IF($H19>K$7,($F16-$F$42)*(OFFSET($F16,-K$7,0)-$F$42),"") -> 3.6199852e+08 | L19: =IF($H19>L$7,($F16-$F$42)*(OFFSET($F16,-L$7,0)-$F$42),"") -> -44593624 | M19: =IF($H19>M$7,($F16-$F$42)*(OFFSET($F16,-M$7,0)-$F$42),"") -> -7.2416078e+08 | N19: =IF($H19>N$7,($F16-$F$42)*(OFFSET($F16,-N$7,0)-$F$42),"") -> -3.2026564e+08 | O19: =IF($H19>O$7,($F16-$F$42)*(OFFSET($F16,-O$7,0)-$F$42),"") -> -9.2913284e+08 | P19: =IF($H19>P$7,($F16-$F$42)*(OFFSET($F16,-P$7,0)-$F$42),"") -> -1.389665e+09 | ... AQ19: =IF($H19>AQ$7,($F16-$F$42)*(OFFSET($F16,-AQ$7,0)-$F$42),"")
E20: 45108 | F20: {=INDEX('Black (Aggregated)'!$N$6:$N$41,MATCH(E20,'Black (Aggregated)'!$M$6:$M$41,0))} -> 73332 | H20: 12 | I20: =IF($H20>I$7,($F17-$F$42)*(OFFSET($F17,-I$7,0)-$F$42),"") -> 1.3375519e+08 | J20: =IF($H20>J$7,($F17-$F$42)*(OFFSET($F17,-J$7,0)-$F$42),"") -> 2.8207859e+08 | K20: =IF($H20>K$7,($F17-$F$42)*(OFFSET($F17,-K$7,0)-$F$42),"") -> 2.7919717e+08 | L20: =IF($H20>L$7,($F17-$F$42)*(OFFSET($F17,-L$7,0)-$F$42),"") -> 32617551 | M20: =IF($H20>M$7,($F17-$F$42)*(OFFSET($F17,-M$7,0)-$F$42),"") -> -4018068.4 | N20: =IF($H20>N$7,($F17-$F$42)*(OFFSET($F17,-N$7,0)-$F$42),"") -> -65249855 | O20: =IF($H20>O$7,($F17-$F$42)*(OFFSET($F17,-O$7,0)-$F$42),"") -> -28857247 | P20: =IF($H20>P$7,($F17-$F$42)*(OFFSET($F17,-P$7,0)-$F$42),"") -> -83718679 | ... AQ20: =IF($H20>AQ$7,($F17-$F$42)*(OFFSET($F17,-AQ$7,0)-$F$42),"")
... E41: 44470 | F41: {=INDEX('Black (Aggregated)'!$N$6:$N$41,MATCH(E41,'Black (Aggregated)'!$M$6:$M$41,0))} -> 105878 | H41: 33 | I41: =IF($H41>I$7,($F38-$F$42)*(OFFSET($F38,-I$7,0)-$F$42),"") -> -5.7431609e+08 | J41: =IF($H41>J$7,($F38-$F$42)*(OFFSET($F38,-J$7,0)-$F$42),"") -> -97142361 | K41: =IF($H41>K$7,($F38-$F$42)*(OFFSET($F38,-K$7,0)-$F$42),"") -> -1.6746728e+09 | L41: =IF($H41>L$7,($F38-$F$42)*(OFFSET($F38,-L$7,0)-$F$42),"") -> -1.3009764e+09 | M41: =IF($H41>M$7,($F38-$F$42)*(OFFSET($F38,-M$7,0)-$F$42),"") -> -1.203204e+09 | N41: =IF($H41>N$7,($F38-$F$42)*(OFFSET($F38,-N$7,0)-$F$42),"") -> -2.330462e+09 | O41: =IF($H41>O$7,($F38-$F$42)*(OFFSET($F38,-O$7,0)-$F$42),"") -> -1.8832508e+09 | P41: =IF($H41>P$7,($F38-$F$42)*(OFFSET($F38,-P$7,0)-$F$42),"") -> -5.7691346e+08 | ... AQ41: =IF($H41>AQ$7,($F38-$F$42)*(OFFSET($F38,-AQ$7,0)-$F$42),"")
E42: Mean | F42: =AVERAGE(F6:F41) -> 124784.42 | H42: 34 | I42: =IF($H42>I$7,($F39-$F$42)*(OFFSET($F39,-I$7,0)-$F$42),"") -> 3.8119439e+09 | J42: =IF($H42>J$7,($F39-$F$42)*(OFFSET($F39,-J$7,0)-$F$42),"") -> -1.0176685e+09 | K42: =IF($H42>K$7,($F39-$F$42)*(OFFSET($F39,-K$7,0)-$F$42),"") -> -1.7213295e+08 | L42: =IF($H42>L$7,($F39-$F$42)*(OFFSET($F39,-L$7,0)-$F$42),"") -> -2.967463e+09 | M42: =IF($H42>M$7,($F39-$F$42)*(OFFSET($F39,-M$7,0)-$F$42),"") -> -2.3052857e+09 | N42: =IF($H42>N$7,($F39-$F$42)*(OFFSET($F39,-N$7,0)-$F$42),"") -> -2.1320364e+09 | O42: =IF($H42>O$7,($F39-$F$42)*(OFFSET($F39,-O$7,0)-$F$42),"") -> -4.1294991e+09 | P42: =IF($H42>P$7,($F39-$F$42)*(OFFSET($F39,-P$7,0)-$F$42),"") -> -3.3370561e+09 | ... AQ42: =IF($H42>AQ$7,($F39-$F$42)*(OFFSET($F39,-AQ$7,0)-$F$42),"")
H43: 35 | I43: =IF($H43>I$7,($F40-$F$42)*(OFFSET($F40,-I$7,0)-$F$42),"") -> 1.7761822e+09 | J43: =IF($H43>J$7,($F40-$F$42)*(OFFSET($F40,-J$7,0)-$F$42),"") -> 1.0023795e+09 | K43: =IF($H43>K$7,($F40-$F$42)*(OFFSET($F40,-K$7,0)-$F$42),"") -> -2.6760363e+08 | L43: =IF($H43>L$7,($F40-$F$42)*(OFFSET($F40,-L$7,0)-$F$42),"") -> -45263660 | M43: =IF($H43>M$7,($F40-$F$42)*(OFFSET($F40,-M$7,0)-$F$42),"") -> -7.8031683e+08 | N43: =IF($H43>N$7,($F40-$F$42)*(OFFSET($F40,-N$7,0)-$F$42),"") -> -6.0619231e+08 | O43: =IF($H43>O$7,($F40-$F$42)*(OFFSET($F40,-O$7,0)-$F$42),"") -> -5.6063509e+08 | P43: =IF($H43>P$7,($F40-$F$42)*(OFFSET($F40,-P$7,0)-$F$42),"") -> -1.085883e+09 | ... AQ43: =IF($H43>AQ$7,($F40-$F$42)*(OFFSET($F40,-AQ$7,0)-$F$42),"")
H44: 36 | I44: =IF($H44>I$7,($F41-$F$42)*(OFFSET($F41,-I$7,0)-$F$42),"") -> -4.085976e+08 | J44: =IF($H44>J$7,($F41-$F$42)*(OFFSET($F41,-J$7,0)-$F$42),"") -> -1.5538538e+09 | K44: =IF($H44>K$7,($F41-$F$42)*(OFFSET($F41,-K$7,0)-$F$42),"") -> -8.7690954e+08 | L44: =IF($H44>L$7,($F41-$F$42)*(OFFSET($F41,-L$7,0)-$F$42),"") -> 2.3410713e+08 | M44: =IF($H44>M$7,($F41-$F$42)*(OFFSET($F41,-M$7,0)-$F$42),"") -> 39597914 | N44: =IF($H44>N$7,($F41-$F$42)*(OFFSET($F41,-N$7,0)-$F$42),"") -> 6.8264296e+08 | O44: =IF($H44>O$7,($F41-$F$42)*(OFFSET($F41,-O$7,0)-$F$42),"") -> 5.3031396e+08 | P44: =IF($H44>P$7,($F41-$F$42)*(OFFSET($F41,-P$7,0)-$F$42),"") -> 4.9045923e+08 | ... AQ44: =IF($H44>AQ$7,($F41-$F$42)*(OFFSET($F41,-AQ$7,0)-$F$42),"") -> 2.2522111e+08
E45: Monthly Sales WH1000-MX5 Silver
E46: Month | F46: Monthly Sales | H46: Cross Correlation | I46: =CORREL(OFFSET($F$47,0,0,37-I$48),OFFSET($F$47,I$48,0,37-I$48)) -> 0.68168544 | J46: =CORREL(OFFSET($F$47,0,0,37-J$48),OFFSET($F$47,J$48,0,37-J$48)) -> 0.20736098 | K46: =CORREL(OFFSET($F$47,0,0,37-K$48),OFFSET($F$47,K$48,0,37-K$48)) -> -0.13131764 | L46: =CORREL(OFFSET($F$47,0,0,37-L$48),OFFSET($F$47,L$48,0,37-L$48)) -> -0.31735294 | M46: =CORREL(OFFSET($F$47,0,0,37-M$48),OFFSET($F$47,M$48,0,37-M$48)) -> -0.48318315 | N46: =CORREL(OFFSET($F$47,0,0,37-N$48),OFFSET($F$47,N$48,0,37-N$48)) -> -0.5909709 | O46: =CORREL(OFFSET($F$47,0,0,37-O$48),OFFSET($F$47,O$48,0,37-O$48)) -> -0.55103263 | P46: =CORREL(OFFSET($F$47,0,0,37-P$48),OFFSET($F$47,P$48,0,37-P$48)) -> -0.40439144 | ... AQ46: =CORREL(OFFSET($F$47,0,0,37-AQ$48),OFFSET($F$47,AQ$48,0,37-AQ$48)) -> 1
E47: 45536 | F47: {=INDEX('Silver (Aggregated)'!$N$6:$N$41,MATCH(E6,'Silver (Aggregated)'!$M$6:$M$41,0))} -> 57705 | H47: ACF value | I47: =SUM(OFFSET(I50,I48,0,36-I48,1))/DEVSQ($F$47:$F$82) -> 0.67903724 | J47: =SUM(OFFSET(J50,J48,0,36-J48,1))/DEVSQ($F$47:$F$82) -> 0.2055203 | K47: =SUM(OFFSET(K50,K48,0,36-K48,1))/DEVSQ($F$47:$F$82) -> -0.12760491 | L47: =SUM(OFFSET(L50,L48,0,36-L48,1))/DEVSQ($F$47:$F$82) -> -0.29324557 | M47: =SUM(OFFSET(M50,M48,0,36-M48,1))/DEVSQ($F$47:$F$82) -> -0.43242684 | N47: =SUM(OFFSET(N50,N48,0,36-N48,1))/DEVSQ($F$47:$F$82) -> -0.52482986 | O47: =SUM(OFFSET(O50,O48,0,36-O48,1))/DEVSQ($F$47:$F$82) -> -0.48649897 | P47: =SUM(OFFSET(P50,P48,0,36-P48,1))/DEVSQ($F$47:$F$82) -> -0.35024219 | ... AQ47: =SUM(OFFSET(AQ50,AQ48,0,36-AQ48,1))/DEVSQ($F$47:$F$82) -> 0.0066677854
E48: 45505 | F48: {=INDEX('Silver (Aggregated)'!$N$6:$N$41,MATCH(E7,'Silver (Aggregated)'!$M$6:$M$41,0))} -> 58140 | H48: Lag | I48: 1 | J48: 2 | K48: 3 | L48: 4 | M48: 5 | N48: 6 | O48: 7 | P48: 8 | Q48: 9 | R48: 10 | S48: 11 | T48: 12 | U48: 13 | V48: 14 | W48: 15 | X48: 16 | Y48: 17 | Z48: 18 | AA48: 19 | AB48: 20 | AC48: 21 | AD48: 22 | AE48: 23 | AF48: 24 | AG48: 25 | AH48: 26 | AI48: 27 | AJ48: 28 | AK48: 29 | AL48: 30 | AM48: 31 | AN48: 32 | AO48: 33 | AP48: 34 | AQ48: 35
E49: 45474 | F49: {=INDEX('Silver (Aggregated)'!$N$6:$N$41,MATCH(E8,'Silver (Aggregated)'!$M$6:$M$41,0))} -> 50461 | H49: Counter
E50: 45444 | F50: {=INDEX('Silver (Aggregated)'!$N$6:$N$41,MATCH(E9,'Silver (Aggregated)'!$M$6:$M$41,0))} -> 53435 | H50: 1 | I50: =IF($H50>I$48,($F47-$F$83)*(OFFSET($F47,-I$48,0)-$F$83),"") | J50: =IF($H50>J$48,($F47-$F$83)*(OFFSET($F47,-J$48,0)-$F$83),"") | K50: =IF($H50>K$48,($F47-$F$83)*(OFFSET($F47,-K$48,0)-$F$83),"") | L50: =IF($H50>L$48,($F47-$F$83)*(OFFSET($F47,-L$48,0)-$F$83),"") | M50: =IF($H50>M$48,($F47-$F$83)*(OFFSET($F47,-M$48,0)-$F$83),"") | N50: =IF($H50>N$48,($F47-$F$83)*(OFFSET($F47,-N$48,0)-$F$83),"") | O50: =IF($H50>O$48,($F47-$F$83)*(OFFSET($F47,-O$48,0)-$F$83),"") | P50: =IF($H50>P$48,($F47-$F$83)*(OFFSET($F47,-P$48,0)-$F$83),"") | ... AQ50: =IF($H50>AQ$48,($F47-$F$83)*(OFFSET($F47,-AQ$48,0)-$F$83),"")
E51: 45413 | F51: {=INDEX('Silver (Aggregated)'!$N$6:$N$41,MATCH(E10,'Silver (Aggregated)'!$M$6:$M$41,0))} -> 64106 | H51: 2 | I51: =IF($H51>I$48,($F48-$F$83)*(OFFSET($F48,-I$48,0)-$F$83),"") -> 93386129 | J51: =IF($H51>J$48,($F48-$F$83)*(OFFSET($F48,-J$48,0)-$F$83),"") | K51: =IF($H51>K$48,($F48-$F$83)*(OFFSET($F48,-K$48,0)-$F$83),"") | L51: =IF($H51>L$48,($F48-$F$83)*(OFFSET($F48,-L$48,0)-$F$83),"") | M51: =IF($H51>M$48,($F48-$F$83)*(OFFSET($F48,-M$48,0)-$F$83),"") | N51: =IF($H51>N$48,($F48-$F$83)*(OFFSET($F48,-N$48,0)-$F$83),"") | O51: =IF($H51>O$48,($F48-$F$83)*(OFFSET($F48,-O$48,0)-$F$83),"") | P51: =IF($H51>P$48,($F48-$F$83)*(OFFSET($F48,-P$48,0)-$F$83),"") | ... AQ51: =IF($H51>AQ$48,($F48-$F$83)*(OFFSET($F48,-AQ$48,0)-$F$83),"")
